supervisor: couldn't chdir to /usr/local/codes/ip_proxy/proxy_verify: ENOENT
supervisor: child process was not spawned
supervisor: couldn't chdir to /usr/local/codes/ip_proxy/proxy_verify: ENOENT
supervisor: child process was not spawned
supervisor: couldn't chdir to /usr/local/codes/ip_proxy/proxy_verify: ENOENT
supervisor: child process was not spawned
supervisor: couldn't chdir to /usr/local/codes/ip_proxy/proxy_verify: ENOENT
supervisor: child process was not spawned
supervisor: couldn't chdir to /usr/local/codes/ip_proxy/proxy_verify: ENOENT
supervisor: child process was not spawned
supervisor: couldn't chdir to /usr/local/codes/ip_proxy/proxy_verify: ENOENT
supervisor: child process was not spawned
supervisor: couldn't chdir to /usr/local/codes/ip_proxy/proxy_verify: ENOENT
supervisor: child process was not spawned
supervisor: couldn't chdir to /usr/local/codes/ip_proxy/proxy_verify: ENOENT
supervisor: child process was not spawned
Traceback (most recent call last):
  File "./main_loop.py", line 3, in <module>
    from proxy_verify.verifier_manager import VerifierManager
ImportError: No module named proxy_verify.verifier_manager
Traceback (most recent call last):
  File "./main_loop.py", line 3, in <module>
    from proxy_verify.verifier_manager import VerifierManager
ImportError: No module named proxy_verify.verifier_manager
Traceback (most recent call last):
  File "./main_loop.py", line 3, in <module>
    from proxy_verify.verifier_manager import VerifierManager
ImportError: No module named proxy_verify.verifier_manager
Traceback (most recent call last):
  File "./main_loop.py", line 3, in <module>
    from proxy_verify.verifier_manager import VerifierManager
ImportError: No module named proxy_verify.verifier_manager
Traceback (most recent call last):
  File "./main_loop.py", line 3, in <module>
    from proxy_verify.verifier_manager import VerifierManager
ImportError: No module named proxy_verify.verifier_manager
Traceback (most recent call last):
  File "./main_loop.py", line 3, in <module>
    from proxy_verify.verifier_manager import VerifierManager
ImportError: No module named proxy_verify.verifier_manager
Traceback (most recent call last):
  File "./main_loop.py", line 3, in <module>
    from proxy_verify.verifier_manager import VerifierManager
ImportError: No module named proxy_verify.verifier_manager
Traceback (most recent call last):
  File "./main_loop.py", line 3, in <module>
    from proxy_verify.verifier_manager import VerifierManager
ImportError: No module named proxy_verify.verifier_manager
Traceback (most recent call last):
  File "./proxy_verify/main_loop.py", line 3, in <module>
    from proxy_verify.verifier_manager import VerifierManager
ImportError: No module named proxy_verify.verifier_manager
Traceback (most recent call last):
  File "./proxy_verify/main_loop.py", line 3, in <module>
    from proxy_verify.verifier_manager import VerifierManager
ImportError: No module named proxy_verify.verifier_manager
Traceback (most recent call last):
  File "./proxy_verify/main_loop.py", line 3, in <module>
    from proxy_verify.verifier_manager import VerifierManager
ImportError: No module named proxy_verify.verifier_manager
Traceback (most recent call last):
  File "./proxy_verify/main_loop.py", line 3, in <module>
    from proxy_verify.verifier_manager import VerifierManager
ImportError: No module named proxy_verify.verifier_manager
Traceback (most recent call last):
  File "./proxy_verify/main_loop.py", line 3, in <module>
    from proxy_verify.verifier_manager import VerifierManager
ImportError: No module named proxy_verify.verifier_manager
Traceback (most recent call last):
  File "./proxy_verify/main_loop.py", line 3, in <module>
    from proxy_verify.verifier_manager import VerifierManager
ImportError: No module named proxy_verify.verifier_manager
Traceback (most recent call last):
  File "./proxy_verify/main_loop.py", line 3, in <module>
    from proxy_verify.verifier_manager import VerifierManager
ImportError: No module named proxy_verify.verifier_manager
Traceback (most recent call last):
  File "./proxy_verify/main_loop.py", line 3, in <module>
    from proxy_verify.verifier_manager import VerifierManager
ImportError: No module named proxy_verify.verifier_manager
Traceback (most recent call last):
  File "./proxy_verify/main_loop.py", line 3, in <module>
    from proxy_verify.verifier_manager import VerifierManager
ImportError: No module named proxy_verify.verifier_manager
Traceback (most recent call last):
  File "./proxy_verify/main_loop.py", line 3, in <module>
    from proxy_verify.verifier_manager import VerifierManager
ImportError: No module named proxy_verify.verifier_manager
Traceback (most recent call last):
  File "./proxy_verify/main_loop.py", line 3, in <module>
    from proxy_verify.verifier_manager import VerifierManager
ImportError: No module named proxy_verify.verifier_manager
Traceback (most recent call last):
  File "./proxy_verify/main_loop.py", line 3, in <module>
    from proxy_verify.verifier_manager import VerifierManager
ImportError: No module named proxy_verify.verifier_manager
Traceback (most recent call last):
  File "./proxy_verify/main_loop.py", line 3, in <module>
    from proxy_verify.verifier_manager import VerifierManager
ImportError: No module named proxy_verify.verifier_manager
Traceback (most recent call last):
  File "./proxy_verify/main_loop.py", line 3, in <module>
    from proxy_verify.verifier_manager import VerifierManager
ImportError: No module named proxy_verify.verifier_manager
Traceback (most recent call last):
  File "./proxy_verify/main_loop.py", line 3, in <module>
    from proxy_verify.verifier_manager import VerifierManager
ImportError: No module named proxy_verify.verifier_manager
Traceback (most recent call last):
  File "./proxy_verify/main_loop.py", line 3, in <module>
    from proxy_verify.verifier_manager import VerifierManager
ImportError: No module named proxy_verify.verifier_manager
Traceback (most recent call last):
  File "./proxy_verify/main_loop.py", line 3, in <module>
    from proxy_verify.verifier_manager import VerifierManager
ImportError: No module named proxy_verify.verifier_manager
Traceback (most recent call last):
  File "./proxy_verify/main_loop.py", line 3, in <module>
    from proxy_verify.verifier_manager import VerifierManager
ImportError: No module named proxy_verify.verifier_manager
Traceback (most recent call last):
  File "./proxy_verify/main_loop.py", line 3, in <module>
    from proxy_verify.verifier_manager import VerifierManager
ImportError: No module named proxy_verify.verifier_manager
Traceback (most recent call last):
  File "./proxy_verify/main_loop.py", line 3, in <module>
    from proxy_verify.verifier_manager import VerifierManager
ImportError: No module named proxy_verify.verifier_manager
Traceback (most recent call last):
  File "./proxy_verify/main_loop.py", line 3, in <module>
    from proxy_verify.verifier_manager import VerifierManager
ImportError: No module named proxy_verify.verifier_manager
Traceback (most recent call last):
  File "./proxy_verify/main_loop.py", line 3, in <module>
    from proxy_verify.verifier_manager import VerifierManager
ImportError: No module named proxy_verify.verifier_manager
Traceback (most recent call last):
  File "./proxy_verify/main_loop.py", line 3, in <module>
    from proxy_verify.verifier_manager import VerifierManager
ImportError: No module named proxy_verify.verifier_manager
Traceback (most recent call last):
  File "./proxy_verify/main_loop.py", line 3, in <module>
    from proxy_verify.verifier_manager import VerifierManager
ImportError: No module named proxy_verify.verifier_manager
Traceback (most recent call last):
  File "./proxy_verify/main_loop.py", line 3, in <module>
    from proxy_verify.verifier_manager import VerifierManager
  File "/usr/local/code/ip_proxy/proxy_verify/verifier_manager.py", line 3, in <module>
    from proxy_verify.verifiers.mayidaili import MayidailiVerify
  File "/usr/local/code/ip_proxy/proxy_verify/verifiers/mayidaili.py", line 6, in <module>
    import requests
ImportError: No module named requests
Traceback (most recent call last):
  File "./proxy_verify/main_loop.py", line 3, in <module>
    from proxy_verify.verifier_manager import VerifierManager
  File "/usr/local/code/ip_proxy/proxy_verify/verifier_manager.py", line 3, in <module>
    from proxy_verify.verifiers.mayidaili import MayidailiVerify
  File "/usr/local/code/ip_proxy/proxy_verify/verifiers/mayidaili.py", line 6, in <module>
    import requests
ImportError: No module named requests
Traceback (most recent call last):
  File "./proxy_verify/main_loop.py", line 3, in <module>
    from proxy_verify.verifier_manager import VerifierManager
  File "/usr/local/code/ip_proxy/proxy_verify/verifier_manager.py", line 3, in <module>
    from proxy_verify.verifiers.mayidaili import MayidailiVerify
  File "/usr/local/code/ip_proxy/proxy_verify/verifiers/mayidaili.py", line 6, in <module>
    import requests
ImportError: No module named requests
Traceback (most recent call last):
  File "./proxy_verify/main_loop.py", line 3, in <module>
    from proxy_verify.verifier_manager import VerifierManager
  File "/usr/local/code/ip_proxy/proxy_verify/verifier_manager.py", line 3, in <module>
    from proxy_verify.verifiers.mayidaili import MayidailiVerify
  File "/usr/local/code/ip_proxy/proxy_verify/verifiers/mayidaili.py", line 6, in <module>
    import requests
ImportError: No module named requests
Traceback (most recent call last):
  File "./proxy_verify/main_loop.py", line 37, in <module>
    app.run()
  File "./proxy_verify/main_loop.py", line 22, in run
    natures = self.schedule_manager.get_natures()
  File "/usr/local/code/ip_proxy/proxy_verify/schedule_manager.py", line 22, in get_natures
    natures = [ v for v in natures]
  File "/usr/local/lib/python2.7/dist-packages/pymongo/cursor.py", line 1114, in next
    if len(self.__data) or self._refresh():
  File "/usr/local/lib/python2.7/dist-packages/pymongo/cursor.py", line 1036, in _refresh
    self.__collation))
  File "/usr/local/lib/python2.7/dist-packages/pymongo/cursor.py", line 873, in __send_message
    **kwargs)
  File "/usr/local/lib/python2.7/dist-packages/pymongo/mongo_client.py", line 888, in _send_message_with_response
    server = topology.select_server(selector)
  File "/usr/local/lib/python2.7/dist-packages/pymongo/topology.py", line 214, in select_server
    address))
  File "/usr/local/lib/python2.7/dist-packages/pymongo/topology.py", line 189, in select_servers
    self._error_message(selector))
pymongo.errors.ServerSelectionTimeoutError: localhost:27017: [Errno 111] Connection refused
Traceback (most recent call last):
  File "./proxy_verify/main_loop.py", line 37, in <module>
    app.run()
  File "./proxy_verify/main_loop.py", line 22, in run
    natures = self.schedule_manager.get_natures()
  File "/usr/local/code/ip_proxy/proxy_verify/schedule_manager.py", line 22, in get_natures
    natures = [ v for v in natures]
  File "/usr/local/lib/python2.7/dist-packages/pymongo/cursor.py", line 1114, in next
    if len(self.__data) or self._refresh():
  File "/usr/local/lib/python2.7/dist-packages/pymongo/cursor.py", line 1036, in _refresh
    self.__collation))
  File "/usr/local/lib/python2.7/dist-packages/pymongo/cursor.py", line 873, in __send_message
    **kwargs)
  File "/usr/local/lib/python2.7/dist-packages/pymongo/mongo_client.py", line 888, in _send_message_with_response
    server = topology.select_server(selector)
  File "/usr/local/lib/python2.7/dist-packages/pymongo/topology.py", line 214, in select_server
    address))
  File "/usr/local/lib/python2.7/dist-packages/pymongo/topology.py", line 189, in select_servers
    self._error_message(selector))
pymongo.errors.ServerSelectionTimeoutError: localhost:27017: [Errno 111] Connection refused
Traceback (most recent call last):
  File "./proxy_verify/main_loop.py", line 37, in <module>
    app.run()
  File "./proxy_verify/main_loop.py", line 22, in run
    natures = self.schedule_manager.get_natures()
  File "/usr/local/code/ip_proxy/proxy_verify/schedule_manager.py", line 22, in get_natures
    natures = [ v for v in natures]
  File "/usr/local/lib/python2.7/dist-packages/pymongo/cursor.py", line 1114, in next
    if len(self.__data) or self._refresh():
  File "/usr/local/lib/python2.7/dist-packages/pymongo/cursor.py", line 1036, in _refresh
    self.__collation))
  File "/usr/local/lib/python2.7/dist-packages/pymongo/cursor.py", line 873, in __send_message
    **kwargs)
  File "/usr/local/lib/python2.7/dist-packages/pymongo/mongo_client.py", line 888, in _send_message_with_response
    server = topology.select_server(selector)
  File "/usr/local/lib/python2.7/dist-packages/pymongo/topology.py", line 214, in select_server
    address))
  File "/usr/local/lib/python2.7/dist-packages/pymongo/topology.py", line 189, in select_servers
    self._error_message(selector))
pymongo.errors.ServerSelectionTimeoutError: localhost:27017: [Errno 111] Connection refused
Traceback (most recent call last):
  File "./proxy_verify/main_loop.py", line 37, in <module>
    app.run()
  File "./proxy_verify/main_loop.py", line 22, in run
    natures = self.schedule_manager.get_natures()
  File "/usr/local/code/ip_proxy/proxy_verify/schedule_manager.py", line 22, in get_natures
    natures = [ v for v in natures]
  File "/usr/local/lib/python2.7/dist-packages/pymongo/cursor.py", line 1114, in next
    if len(self.__data) or self._refresh():
  File "/usr/local/lib/python2.7/dist-packages/pymongo/cursor.py", line 1036, in _refresh
    self.__collation))
  File "/usr/local/lib/python2.7/dist-packages/pymongo/cursor.py", line 873, in __send_message
    **kwargs)
  File "/usr/local/lib/python2.7/dist-packages/pymongo/mongo_client.py", line 888, in _send_message_with_response
    server = topology.select_server(selector)
  File "/usr/local/lib/python2.7/dist-packages/pymongo/topology.py", line 214, in select_server
    address))
  File "/usr/local/lib/python2.7/dist-packages/pymongo/topology.py", line 189, in select_servers
    self._error_message(selector))
pymongo.errors.ServerSelectionTimeoutError: localhost:27017: [Errno 111] Connection refused
Traceback (most recent call last):
  File "./proxy_verify/main_loop.py", line 37, in <module>
    app.run()
  File "./proxy_verify/main_loop.py", line 22, in run
    natures = self.schedule_manager.get_natures()
  File "/usr/local/code/ip_proxy/proxy_verify/schedule_manager.py", line 22, in get_natures
    natures = [ v for v in natures]
  File "/usr/local/lib/python2.7/dist-packages/pymongo/cursor.py", line 1114, in next
    if len(self.__data) or self._refresh():
  File "/usr/local/lib/python2.7/dist-packages/pymongo/cursor.py", line 1036, in _refresh
    self.__collation))
  File "/usr/local/lib/python2.7/dist-packages/pymongo/cursor.py", line 873, in __send_message
    **kwargs)
  File "/usr/local/lib/python2.7/dist-packages/pymongo/mongo_client.py", line 888, in _send_message_with_response
    server = topology.select_server(selector)
  File "/usr/local/lib/python2.7/dist-packages/pymongo/topology.py", line 214, in select_server
    address))
  File "/usr/local/lib/python2.7/dist-packages/pymongo/topology.py", line 189, in select_servers
    self._error_message(selector))
pymongo.errors.ServerSelectionTimeoutError: localhost:27017: [Errno 111] Connection refused
Traceback (most recent call last):
  File "./proxy_verify/main_loop.py", line 37, in <module>
    app.run()
  File "./proxy_verify/main_loop.py", line 22, in run
    natures = self.schedule_manager.get_natures()
  File "/usr/local/code/ip_proxy/proxy_verify/schedule_manager.py", line 22, in get_natures
    natures = [ v for v in natures]
  File "/usr/local/lib/python2.7/dist-packages/pymongo/cursor.py", line 1114, in next
    if len(self.__data) or self._refresh():
  File "/usr/local/lib/python2.7/dist-packages/pymongo/cursor.py", line 1036, in _refresh
    self.__collation))
  File "/usr/local/lib/python2.7/dist-packages/pymongo/cursor.py", line 873, in __send_message
    **kwargs)
  File "/usr/local/lib/python2.7/dist-packages/pymongo/mongo_client.py", line 888, in _send_message_with_response
    server = topology.select_server(selector)
  File "/usr/local/lib/python2.7/dist-packages/pymongo/topology.py", line 214, in select_server
    address))
  File "/usr/local/lib/python2.7/dist-packages/pymongo/topology.py", line 189, in select_servers
    self._error_message(selector))
pymongo.errors.ServerSelectionTimeoutError: localhost:27017: [Errno 111] Connection refused
Traceback (most recent call last):
  File "./proxy_verify/main_loop.py", line 37, in <module>
    app.run()
  File "./proxy_verify/main_loop.py", line 22, in run
    natures = self.schedule_manager.get_natures()
  File "/usr/local/code/ip_proxy/proxy_verify/schedule_manager.py", line 22, in get_natures
    natures = [ v for v in natures]
  File "/usr/local/lib/python2.7/dist-packages/pymongo/cursor.py", line 1114, in next
    if len(self.__data) or self._refresh():
  File "/usr/local/lib/python2.7/dist-packages/pymongo/cursor.py", line 1036, in _refresh
    self.__collation))
  File "/usr/local/lib/python2.7/dist-packages/pymongo/cursor.py", line 873, in __send_message
    **kwargs)
  File "/usr/local/lib/python2.7/dist-packages/pymongo/mongo_client.py", line 888, in _send_message_with_response
    server = topology.select_server(selector)
  File "/usr/local/lib/python2.7/dist-packages/pymongo/topology.py", line 214, in select_server
    address))
  File "/usr/local/lib/python2.7/dist-packages/pymongo/topology.py", line 189, in select_servers
    self._error_message(selector))
pymongo.errors.ServerSelectionTimeoutError: localhost:27017: [Errno 111] Connection refused
Traceback (most recent call last):
  File "./proxy_verify/main_loop.py", line 37, in <module>
    app.run()
  File "./proxy_verify/main_loop.py", line 22, in run
    natures = self.schedule_manager.get_natures()
  File "/usr/local/code/ip_proxy/proxy_verify/schedule_manager.py", line 22, in get_natures
    natures = [ v for v in natures]
  File "/usr/local/lib/python2.7/dist-packages/pymongo/cursor.py", line 1114, in next
    if len(self.__data) or self._refresh():
  File "/usr/local/lib/python2.7/dist-packages/pymongo/cursor.py", line 1036, in _refresh
    self.__collation))
  File "/usr/local/lib/python2.7/dist-packages/pymongo/cursor.py", line 873, in __send_message
    **kwargs)
  File "/usr/local/lib/python2.7/dist-packages/pymongo/mongo_client.py", line 888, in _send_message_with_response
    server = topology.select_server(selector)
  File "/usr/local/lib/python2.7/dist-packages/pymongo/topology.py", line 214, in select_server
    address))
  File "/usr/local/lib/python2.7/dist-packages/pymongo/topology.py", line 189, in select_servers
    self._error_message(selector))
pymongo.errors.ServerSelectionTimeoutError: localhost:27017: [Errno 111] Connection refused
Traceback (most recent call last):
  File "./proxy_verify/main_loop.py", line 37, in <module>
    app.run()
  File "./proxy_verify/main_loop.py", line 22, in run
    natures = self.schedule_manager.get_natures()
  File "/usr/local/code/ip_proxy/proxy_verify/schedule_manager.py", line 22, in get_natures
    natures = [ v for v in natures]
  File "/usr/local/lib/python2.7/dist-packages/pymongo/cursor.py", line 1114, in next
    if len(self.__data) or self._refresh():
  File "/usr/local/lib/python2.7/dist-packages/pymongo/cursor.py", line 1036, in _refresh
    self.__collation))
  File "/usr/local/lib/python2.7/dist-packages/pymongo/cursor.py", line 873, in __send_message
    **kwargs)
  File "/usr/local/lib/python2.7/dist-packages/pymongo/mongo_client.py", line 888, in _send_message_with_response
    server = topology.select_server(selector)
  File "/usr/local/lib/python2.7/dist-packages/pymongo/topology.py", line 214, in select_server
    address))
  File "/usr/local/lib/python2.7/dist-packages/pymongo/topology.py", line 189, in select_servers
    self._error_message(selector))
pymongo.errors.ServerSelectionTimeoutError: localhost:27017: [Errno 111] Connection refused
Traceback (most recent call last):
  File "./proxy_verify/main_loop.py", line 37, in <module>
    app.run()
  File "./proxy_verify/main_loop.py", line 22, in run
    natures = self.schedule_manager.get_natures()
  File "/usr/local/code/ip_proxy/proxy_verify/schedule_manager.py", line 22, in get_natures
    natures = [ v for v in natures]
  File "/usr/local/lib/python2.7/dist-packages/pymongo/cursor.py", line 1114, in next
    if len(self.__data) or self._refresh():
  File "/usr/local/lib/python2.7/dist-packages/pymongo/cursor.py", line 1036, in _refresh
    self.__collation))
  File "/usr/local/lib/python2.7/dist-packages/pymongo/cursor.py", line 873, in __send_message
    **kwargs)
  File "/usr/local/lib/python2.7/dist-packages/pymongo/mongo_client.py", line 888, in _send_message_with_response
    server = topology.select_server(selector)
  File "/usr/local/lib/python2.7/dist-packages/pymongo/topology.py", line 214, in select_server
    address))
  File "/usr/local/lib/python2.7/dist-packages/pymongo/topology.py", line 189, in select_servers
    self._error_message(selector))
pymongo.errors.ServerSelectionTimeoutError: localhost:27017: [Errno 111] Connection refused
Traceback (most recent call last):
  File "./proxy_verify/main_loop.py", line 37, in <module>
    app.run()
  File "./proxy_verify/main_loop.py", line 22, in run
    natures = self.schedule_manager.get_natures()
  File "/usr/local/code/ip_proxy/proxy_verify/schedule_manager.py", line 22, in get_natures
    natures = [ v for v in natures]
  File "/usr/local/lib/python2.7/dist-packages/pymongo/cursor.py", line 1114, in next
    if len(self.__data) or self._refresh():
  File "/usr/local/lib/python2.7/dist-packages/pymongo/cursor.py", line 1036, in _refresh
    self.__collation))
  File "/usr/local/lib/python2.7/dist-packages/pymongo/cursor.py", line 873, in __send_message
    **kwargs)
  File "/usr/local/lib/python2.7/dist-packages/pymongo/mongo_client.py", line 888, in _send_message_with_response
    server = topology.select_server(selector)
  File "/usr/local/lib/python2.7/dist-packages/pymongo/topology.py", line 214, in select_server
    address))
  File "/usr/local/lib/python2.7/dist-packages/pymongo/topology.py", line 189, in select_servers
    self._error_message(selector))
pymongo.errors.ServerSelectionTimeoutError: localhost:27017: [Errno 111] Connection refused
Traceback (most recent call last):
  File "./proxy_verify/main_loop.py", line 37, in <module>
    app.run()
  File "./proxy_verify/main_loop.py", line 22, in run
    natures = self.schedule_manager.get_natures()
  File "/usr/local/code/ip_proxy/proxy_verify/schedule_manager.py", line 22, in get_natures
    natures = [ v for v in natures]
  File "/usr/local/lib/python2.7/dist-packages/pymongo/cursor.py", line 1114, in next
    if len(self.__data) or self._refresh():
  File "/usr/local/lib/python2.7/dist-packages/pymongo/cursor.py", line 1036, in _refresh
    self.__collation))
  File "/usr/local/lib/python2.7/dist-packages/pymongo/cursor.py", line 873, in __send_message
    **kwargs)
  File "/usr/local/lib/python2.7/dist-packages/pymongo/mongo_client.py", line 888, in _send_message_with_response
    server = topology.select_server(selector)
  File "/usr/local/lib/python2.7/dist-packages/pymongo/topology.py", line 214, in select_server
    address))
  File "/usr/local/lib/python2.7/dist-packages/pymongo/topology.py", line 189, in select_servers
    self._error_message(selector))
pymongo.errors.ServerSelectionTimeoutError: localhost:27017: [Errno 111] Connection refused
Traceback (most recent call last):
  File "./proxy_verify/main_loop.py", line 37, in <module>
    app.run()
  File "./proxy_verify/main_loop.py", line 22, in run
    natures = self.schedule_manager.get_natures()
  File "/usr/local/code/ip_proxy/proxy_verify/schedule_manager.py", line 22, in get_natures
    natures = [ v for v in natures]
  File "/usr/local/lib/python2.7/dist-packages/pymongo/cursor.py", line 1114, in next
    if len(self.__data) or self._refresh():
  File "/usr/local/lib/python2.7/dist-packages/pymongo/cursor.py", line 1036, in _refresh
    self.__collation))
  File "/usr/local/lib/python2.7/dist-packages/pymongo/cursor.py", line 873, in __send_message
    **kwargs)
  File "/usr/local/lib/python2.7/dist-packages/pymongo/mongo_client.py", line 888, in _send_message_with_response
    server = topology.select_server(selector)
  File "/usr/local/lib/python2.7/dist-packages/pymongo/topology.py", line 214, in select_server
    address))
  File "/usr/local/lib/python2.7/dist-packages/pymongo/topology.py", line 189, in select_servers
    self._error_message(selector))
pymongo.errors.ServerSelectionTimeoutError: localhost:27017: [Errno 111] Connection refused
Traceback (most recent call last):
  File "./proxy_verify/main_loop.py", line 37, in <module>
    app.run()
  File "./proxy_verify/main_loop.py", line 22, in run
    natures = self.schedule_manager.get_natures()
  File "/usr/local/code/ip_proxy/proxy_verify/schedule_manager.py", line 22, in get_natures
    natures = [ v for v in natures]
  File "/usr/local/lib/python2.7/dist-packages/pymongo/cursor.py", line 1114, in next
    if len(self.__data) or self._refresh():
  File "/usr/local/lib/python2.7/dist-packages/pymongo/cursor.py", line 1036, in _refresh
    self.__collation))
  File "/usr/local/lib/python2.7/dist-packages/pymongo/cursor.py", line 873, in __send_message
    **kwargs)
  File "/usr/local/lib/python2.7/dist-packages/pymongo/mongo_client.py", line 888, in _send_message_with_response
    server = topology.select_server(selector)
  File "/usr/local/lib/python2.7/dist-packages/pymongo/topology.py", line 214, in select_server
    address))
  File "/usr/local/lib/python2.7/dist-packages/pymongo/topology.py", line 189, in select_servers
    self._error_message(selector))
pymongo.errors.ServerSelectionTimeoutError: localhost:27017: [Errno 111] Connection refused
Traceback (most recent call last):
  File "./proxy_verify/main_loop.py", line 37, in <module>
    app.run()
  File "./proxy_verify/main_loop.py", line 22, in run
    natures = self.schedule_manager.get_natures()
  File "/usr/local/code/ip_proxy/proxy_verify/schedule_manager.py", line 22, in get_natures
    natures = [ v for v in natures]
  File "/usr/local/lib/python2.7/dist-packages/pymongo/cursor.py", line 1114, in next
    if len(self.__data) or self._refresh():
  File "/usr/local/lib/python2.7/dist-packages/pymongo/cursor.py", line 1036, in _refresh
    self.__collation))
  File "/usr/local/lib/python2.7/dist-packages/pymongo/cursor.py", line 873, in __send_message
    **kwargs)
  File "/usr/local/lib/python2.7/dist-packages/pymongo/mongo_client.py", line 888, in _send_message_with_response
    server = topology.select_server(selector)
  File "/usr/local/lib/python2.7/dist-packages/pymongo/topology.py", line 214, in select_server
    address))
  File "/usr/local/lib/python2.7/dist-packages/pymongo/topology.py", line 189, in select_servers
    self._error_message(selector))
pymongo.errors.ServerSelectionTimeoutError: localhost:27017: [Errno 111] Connection refused
Traceback (most recent call last):
  File "./proxy_verify/main_loop.py", line 37, in <module>
    app.run()
  File "./proxy_verify/main_loop.py", line 22, in run
    natures = self.schedule_manager.get_natures()
  File "/usr/local/code/ip_proxy/proxy_verify/schedule_manager.py", line 22, in get_natures
    natures = [ v for v in natures]
  File "/usr/local/lib/python2.7/dist-packages/pymongo/cursor.py", line 1114, in next
    if len(self.__data) or self._refresh():
  File "/usr/local/lib/python2.7/dist-packages/pymongo/cursor.py", line 1036, in _refresh
    self.__collation))
  File "/usr/local/lib/python2.7/dist-packages/pymongo/cursor.py", line 873, in __send_message
    **kwargs)
  File "/usr/local/lib/python2.7/dist-packages/pymongo/mongo_client.py", line 888, in _send_message_with_response
    server = topology.select_server(selector)
  File "/usr/local/lib/python2.7/dist-packages/pymongo/topology.py", line 214, in select_server
    address))
  File "/usr/local/lib/python2.7/dist-packages/pymongo/topology.py", line 189, in select_servers
    self._error_message(selector))
pymongo.errors.ServerSelectionTimeoutError: localhost:27017: [Errno 111] Connection refused
Traceback (most recent call last):
  File "./proxy_verify/main_loop.py", line 37, in <module>
    app.run()
  File "./proxy_verify/main_loop.py", line 22, in run
    natures = self.schedule_manager.get_natures()
  File "/usr/local/code/ip_proxy/proxy_verify/schedule_manager.py", line 22, in get_natures
    natures = [ v for v in natures]
  File "/usr/local/lib/python2.7/dist-packages/pymongo/cursor.py", line 1114, in next
    if len(self.__data) or self._refresh():
  File "/usr/local/lib/python2.7/dist-packages/pymongo/cursor.py", line 1036, in _refresh
    self.__collation))
  File "/usr/local/lib/python2.7/dist-packages/pymongo/cursor.py", line 873, in __send_message
    **kwargs)
  File "/usr/local/lib/python2.7/dist-packages/pymongo/mongo_client.py", line 888, in _send_message_with_response
    server = topology.select_server(selector)
  File "/usr/local/lib/python2.7/dist-packages/pymongo/topology.py", line 214, in select_server
    address))
  File "/usr/local/lib/python2.7/dist-packages/pymongo/topology.py", line 189, in select_servers
    self._error_message(selector))
pymongo.errors.ServerSelectionTimeoutError: localhost:27017: [Errno 111] Connection refused
Traceback (most recent call last):
  File "./proxy_verify/main_loop.py", line 37, in <module>
    app.run()
  File "./proxy_verify/main_loop.py", line 22, in run
    natures = self.schedule_manager.get_natures()
  File "/usr/local/code/ip_proxy/proxy_verify/schedule_manager.py", line 22, in get_natures
    natures = [ v for v in natures]
  File "/usr/local/lib/python2.7/dist-packages/pymongo/cursor.py", line 1114, in next
    if len(self.__data) or self._refresh():
  File "/usr/local/lib/python2.7/dist-packages/pymongo/cursor.py", line 1036, in _refresh
    self.__collation))
  File "/usr/local/lib/python2.7/dist-packages/pymongo/cursor.py", line 873, in __send_message
    **kwargs)
  File "/usr/local/lib/python2.7/dist-packages/pymongo/mongo_client.py", line 888, in _send_message_with_response
    server = topology.select_server(selector)
  File "/usr/local/lib/python2.7/dist-packages/pymongo/topology.py", line 214, in select_server
    address))
  File "/usr/local/lib/python2.7/dist-packages/pymongo/topology.py", line 189, in select_servers
    self._error_message(selector))
pymongo.errors.ServerSelectionTimeoutError: localhost:27017: [Errno 111] Connection refused
Traceback (most recent call last):
  File "./proxy_verify/main_loop.py", line 37, in <module>
    app.run()
  File "./proxy_verify/main_loop.py", line 22, in run
    natures = self.schedule_manager.get_natures()
  File "/usr/local/code/ip_proxy/proxy_verify/schedule_manager.py", line 22, in get_natures
    natures = [ v for v in natures]
  File "/usr/local/lib/python2.7/dist-packages/pymongo/cursor.py", line 1114, in next
    if len(self.__data) or self._refresh():
  File "/usr/local/lib/python2.7/dist-packages/pymongo/cursor.py", line 1036, in _refresh
    self.__collation))
  File "/usr/local/lib/python2.7/dist-packages/pymongo/cursor.py", line 873, in __send_message
    **kwargs)
  File "/usr/local/lib/python2.7/dist-packages/pymongo/mongo_client.py", line 888, in _send_message_with_response
    server = topology.select_server(selector)
  File "/usr/local/lib/python2.7/dist-packages/pymongo/topology.py", line 214, in select_server
    address))
  File "/usr/local/lib/python2.7/dist-packages/pymongo/topology.py", line 189, in select_servers
    self._error_message(selector))
pymongo.errors.ServerSelectionTimeoutError: localhost:27017: [Errno 111] Connection refused
Traceback (most recent call last):
  File "./proxy_verify/main_loop.py", line 37, in <module>
    app.run()
  File "./proxy_verify/main_loop.py", line 22, in run
    natures = self.schedule_manager.get_natures()
  File "/usr/local/code/ip_proxy/proxy_verify/schedule_manager.py", line 22, in get_natures
    natures = [ v for v in natures]
  File "/usr/local/lib/python2.7/dist-packages/pymongo/cursor.py", line 1114, in next
    if len(self.__data) or self._refresh():
  File "/usr/local/lib/python2.7/dist-packages/pymongo/cursor.py", line 1036, in _refresh
    self.__collation))
  File "/usr/local/lib/python2.7/dist-packages/pymongo/cursor.py", line 873, in __send_message
    **kwargs)
  File "/usr/local/lib/python2.7/dist-packages/pymongo/mongo_client.py", line 888, in _send_message_with_response
    server = topology.select_server(selector)
  File "/usr/local/lib/python2.7/dist-packages/pymongo/topology.py", line 214, in select_server
    address))
  File "/usr/local/lib/python2.7/dist-packages/pymongo/topology.py", line 189, in select_servers
    self._error_message(selector))
pymongo.errors.ServerSelectionTimeoutError: localhost:27017: [Errno 111] Connection refused
Traceback (most recent call last):
  File "./proxy_verify/main_loop.py", line 37, in <module>
    app.run()
  File "./proxy_verify/main_loop.py", line 22, in run
    natures = self.schedule_manager.get_natures()
  File "/usr/local/code/ip_proxy/proxy_verify/schedule_manager.py", line 22, in get_natures
    natures = [ v for v in natures]
  File "/usr/local/lib/python2.7/dist-packages/pymongo/cursor.py", line 1114, in next
    if len(self.__data) or self._refresh():
  File "/usr/local/lib/python2.7/dist-packages/pymongo/cursor.py", line 1036, in _refresh
    self.__collation))
  File "/usr/local/lib/python2.7/dist-packages/pymongo/cursor.py", line 873, in __send_message
    **kwargs)
  File "/usr/local/lib/python2.7/dist-packages/pymongo/mongo_client.py", line 888, in _send_message_with_response
    server = topology.select_server(selector)
  File "/usr/local/lib/python2.7/dist-packages/pymongo/topology.py", line 214, in select_server
    address))
  File "/usr/local/lib/python2.7/dist-packages/pymongo/topology.py", line 189, in select_servers
    self._error_message(selector))
pymongo.errors.ServerSelectionTimeoutError: localhost:27017: [Errno 111] Connection refused
Traceback (most recent call last):
  File "./proxy_verify/main_loop.py", line 37, in <module>
    app.run()
  File "./proxy_verify/main_loop.py", line 22, in run
    natures = self.schedule_manager.get_natures()
  File "/usr/local/code/ip_proxy/proxy_verify/schedule_manager.py", line 22, in get_natures
    natures = [ v for v in natures]
  File "/usr/local/lib/python2.7/dist-packages/pymongo/cursor.py", line 1114, in next
    if len(self.__data) or self._refresh():
  File "/usr/local/lib/python2.7/dist-packages/pymongo/cursor.py", line 1036, in _refresh
    self.__collation))
  File "/usr/local/lib/python2.7/dist-packages/pymongo/cursor.py", line 873, in __send_message
    **kwargs)
  File "/usr/local/lib/python2.7/dist-packages/pymongo/mongo_client.py", line 888, in _send_message_with_response
    server = topology.select_server(selector)
  File "/usr/local/lib/python2.7/dist-packages/pymongo/topology.py", line 214, in select_server
    address))
  File "/usr/local/lib/python2.7/dist-packages/pymongo/topology.py", line 189, in select_servers
    self._error_message(selector))
pymongo.errors.ServerSelectionTimeoutError: localhost:27017: [Errno 111] Connection refused
Traceback (most recent call last):
  File "./proxy_verify/main_loop.py", line 37, in <module>
    app.run()
  File "./proxy_verify/main_loop.py", line 22, in run
    natures = self.schedule_manager.get_natures()
  File "/usr/local/code/ip_proxy/proxy_verify/schedule_manager.py", line 22, in get_natures
    natures = [ v for v in natures]
  File "/usr/local/lib/python2.7/dist-packages/pymongo/cursor.py", line 1114, in next
    if len(self.__data) or self._refresh():
  File "/usr/local/lib/python2.7/dist-packages/pymongo/cursor.py", line 1036, in _refresh
    self.__collation))
  File "/usr/local/lib/python2.7/dist-packages/pymongo/cursor.py", line 873, in __send_message
    **kwargs)
  File "/usr/local/lib/python2.7/dist-packages/pymongo/mongo_client.py", line 888, in _send_message_with_response
    server = topology.select_server(selector)
  File "/usr/local/lib/python2.7/dist-packages/pymongo/topology.py", line 214, in select_server
    address))
  File "/usr/local/lib/python2.7/dist-packages/pymongo/topology.py", line 189, in select_servers
    self._error_message(selector))
pymongo.errors.ServerSelectionTimeoutError: localhost:27017: [Errno 111] Connection refused
Traceback (most recent call last):
  File "./proxy_verify/main_loop.py", line 37, in <module>
    app.run()
  File "./proxy_verify/main_loop.py", line 22, in run
    natures = self.schedule_manager.get_natures()
  File "/usr/local/code/ip_proxy/proxy_verify/schedule_manager.py", line 22, in get_natures
    natures = [ v for v in natures]
  File "/usr/local/lib/python2.7/dist-packages/pymongo/cursor.py", line 1114, in next
    if len(self.__data) or self._refresh():
  File "/usr/local/lib/python2.7/dist-packages/pymongo/cursor.py", line 1036, in _refresh
    self.__collation))
  File "/usr/local/lib/python2.7/dist-packages/pymongo/cursor.py", line 873, in __send_message
    **kwargs)
  File "/usr/local/lib/python2.7/dist-packages/pymongo/mongo_client.py", line 888, in _send_message_with_response
    server = topology.select_server(selector)
  File "/usr/local/lib/python2.7/dist-packages/pymongo/topology.py", line 214, in select_server
    address))
  File "/usr/local/lib/python2.7/dist-packages/pymongo/topology.py", line 189, in select_servers
    self._error_message(selector))
pymongo.errors.ServerSelectionTimeoutError: localhost:27017: [Errno 111] Connection refused
Traceback (most recent call last):
  File "./proxy_verify/main_loop.py", line 37, in <module>
    app.run()
  File "./proxy_verify/main_loop.py", line 22, in run
    natures = self.schedule_manager.get_natures()
  File "/usr/local/code/ip_proxy/proxy_verify/schedule_manager.py", line 22, in get_natures
    natures = [ v for v in natures]
  File "/usr/local/lib/python2.7/dist-packages/pymongo/cursor.py", line 1114, in next
    if len(self.__data) or self._refresh():
  File "/usr/local/lib/python2.7/dist-packages/pymongo/cursor.py", line 1036, in _refresh
    self.__collation))
  File "/usr/local/lib/python2.7/dist-packages/pymongo/cursor.py", line 873, in __send_message
    **kwargs)
  File "/usr/local/lib/python2.7/dist-packages/pymongo/mongo_client.py", line 888, in _send_message_with_response
    server = topology.select_server(selector)
  File "/usr/local/lib/python2.7/dist-packages/pymongo/topology.py", line 214, in select_server
    address))
  File "/usr/local/lib/python2.7/dist-packages/pymongo/topology.py", line 189, in select_servers
    self._error_message(selector))
pymongo.errors.ServerSelectionTimeoutError: localhost:27017: [Errno 111] Connection refused
Traceback (most recent call last):
  File "./proxy_verify/main_loop.py", line 37, in <module>
    app.run()
  File "./proxy_verify/main_loop.py", line 22, in run
    natures = self.schedule_manager.get_natures()
  File "/usr/local/code/ip_proxy/proxy_verify/schedule_manager.py", line 22, in get_natures
    natures = [ v for v in natures]
  File "/usr/local/lib/python2.7/dist-packages/pymongo/cursor.py", line 1114, in next
    if len(self.__data) or self._refresh():
  File "/usr/local/lib/python2.7/dist-packages/pymongo/cursor.py", line 1036, in _refresh
    self.__collation))
  File "/usr/local/lib/python2.7/dist-packages/pymongo/cursor.py", line 873, in __send_message
    **kwargs)
  File "/usr/local/lib/python2.7/dist-packages/pymongo/mongo_client.py", line 888, in _send_message_with_response
    server = topology.select_server(selector)
  File "/usr/local/lib/python2.7/dist-packages/pymongo/topology.py", line 214, in select_server
    address))
  File "/usr/local/lib/python2.7/dist-packages/pymongo/topology.py", line 189, in select_servers
    self._error_message(selector))
pymongo.errors.ServerSelectionTimeoutError: localhost:27017: [Errno 111] Connection refused
Traceback (most recent call last):
  File "./proxy_verify/main_loop.py", line 37, in <module>
    app.run()
  File "./proxy_verify/main_loop.py", line 22, in run
    natures = self.schedule_manager.get_natures()
  File "/usr/local/code/ip_proxy/proxy_verify/schedule_manager.py", line 22, in get_natures
    natures = [ v for v in natures]
  File "/usr/local/lib/python2.7/dist-packages/pymongo/cursor.py", line 1114, in next
    if len(self.__data) or self._refresh():
  File "/usr/local/lib/python2.7/dist-packages/pymongo/cursor.py", line 1036, in _refresh
    self.__collation))
  File "/usr/local/lib/python2.7/dist-packages/pymongo/cursor.py", line 873, in __send_message
    **kwargs)
  File "/usr/local/lib/python2.7/dist-packages/pymongo/mongo_client.py", line 888, in _send_message_with_response
    server = topology.select_server(selector)
  File "/usr/local/lib/python2.7/dist-packages/pymongo/topology.py", line 214, in select_server
    address))
  File "/usr/local/lib/python2.7/dist-packages/pymongo/topology.py", line 189, in select_servers
    self._error_message(selector))
pymongo.errors.ServerSelectionTimeoutError: localhost:27017: [Errno 111] Connection refused
Traceback (most recent call last):
  File "./proxy_verify/main_loop.py", line 37, in <module>
    app.run()
  File "./proxy_verify/main_loop.py", line 22, in run
    natures = self.schedule_manager.get_natures()
  File "/usr/local/code/ip_proxy/proxy_verify/schedule_manager.py", line 22, in get_natures
    natures = [ v for v in natures]
  File "/usr/local/lib/python2.7/dist-packages/pymongo/cursor.py", line 1114, in next
    if len(self.__data) or self._refresh():
  File "/usr/local/lib/python2.7/dist-packages/pymongo/cursor.py", line 1036, in _refresh
    self.__collation))
  File "/usr/local/lib/python2.7/dist-packages/pymongo/cursor.py", line 873, in __send_message
    **kwargs)
  File "/usr/local/lib/python2.7/dist-packages/pymongo/mongo_client.py", line 888, in _send_message_with_response
    server = topology.select_server(selector)
  File "/usr/local/lib/python2.7/dist-packages/pymongo/topology.py", line 214, in select_server
    address))
  File "/usr/local/lib/python2.7/dist-packages/pymongo/topology.py", line 189, in select_servers
    self._error_message(selector))
pymongo.errors.ServerSelectionTimeoutError: localhost:27017: [Errno 111] Connection refused
Traceback (most recent call last):
  File "./proxy_verify/main_loop.py", line 37, in <module>
    app.run()
  File "./proxy_verify/main_loop.py", line 22, in run
    natures = self.schedule_manager.get_natures()
  File "/usr/local/code/ip_proxy/proxy_verify/schedule_manager.py", line 22, in get_natures
    natures = [ v for v in natures]
  File "/usr/local/lib/python2.7/dist-packages/pymongo/cursor.py", line 1114, in next
    if len(self.__data) or self._refresh():
  File "/usr/local/lib/python2.7/dist-packages/pymongo/cursor.py", line 1036, in _refresh
    self.__collation))
  File "/usr/local/lib/python2.7/dist-packages/pymongo/cursor.py", line 873, in __send_message
    **kwargs)
  File "/usr/local/lib/python2.7/dist-packages/pymongo/mongo_client.py", line 888, in _send_message_with_response
    server = topology.select_server(selector)
  File "/usr/local/lib/python2.7/dist-packages/pymongo/topology.py", line 214, in select_server
    address))
  File "/usr/local/lib/python2.7/dist-packages/pymongo/topology.py", line 189, in select_servers
    self._error_message(selector))
pymongo.errors.ServerSelectionTimeoutError: localhost:27017: [Errno 111] Connection refused
Traceback (most recent call last):
  File "./proxy_verify/main_loop.py", line 37, in <module>
    app.run()
  File "./proxy_verify/main_loop.py", line 22, in run
    natures = self.schedule_manager.get_natures()
  File "/usr/local/code/ip_proxy/proxy_verify/schedule_manager.py", line 22, in get_natures
    natures = [ v for v in natures]
  File "/usr/local/lib/python2.7/dist-packages/pymongo/cursor.py", line 1114, in next
    if len(self.__data) or self._refresh():
  File "/usr/local/lib/python2.7/dist-packages/pymongo/cursor.py", line 1036, in _refresh
    self.__collation))
  File "/usr/local/lib/python2.7/dist-packages/pymongo/cursor.py", line 873, in __send_message
    **kwargs)
  File "/usr/local/lib/python2.7/dist-packages/pymongo/mongo_client.py", line 888, in _send_message_with_response
    server = topology.select_server(selector)
  File "/usr/local/lib/python2.7/dist-packages/pymongo/topology.py", line 214, in select_server
    address))
  File "/usr/local/lib/python2.7/dist-packages/pymongo/topology.py", line 189, in select_servers
    self._error_message(selector))
pymongo.errors.ServerSelectionTimeoutError: localhost:27017: [Errno 111] Connection refused
Traceback (most recent call last):
  File "./proxy_verify/main_loop.py", line 37, in <module>
    app.run()
  File "./proxy_verify/main_loop.py", line 22, in run
    natures = self.schedule_manager.get_natures()
  File "/usr/local/code/ip_proxy/proxy_verify/schedule_manager.py", line 22, in get_natures
    natures = [ v for v in natures]
  File "/usr/local/lib/python2.7/dist-packages/pymongo/cursor.py", line 1114, in next
    if len(self.__data) or self._refresh():
  File "/usr/local/lib/python2.7/dist-packages/pymongo/cursor.py", line 1036, in _refresh
    self.__collation))
  File "/usr/local/lib/python2.7/dist-packages/pymongo/cursor.py", line 873, in __send_message
    **kwargs)
  File "/usr/local/lib/python2.7/dist-packages/pymongo/mongo_client.py", line 888, in _send_message_with_response
    server = topology.select_server(selector)
  File "/usr/local/lib/python2.7/dist-packages/pymongo/topology.py", line 214, in select_server
    address))
  File "/usr/local/lib/python2.7/dist-packages/pymongo/topology.py", line 189, in select_servers
    self._error_message(selector))
pymongo.errors.ServerSelectionTimeoutError: localhost:27017: [Errno 111] Connection refused
Traceback (most recent call last):
  File "./proxy_verify/main_loop.py", line 37, in <module>
    app.run()
  File "./proxy_verify/main_loop.py", line 22, in run
    natures = self.schedule_manager.get_natures()
  File "/usr/local/code/ip_proxy/proxy_verify/schedule_manager.py", line 22, in get_natures
    natures = [ v for v in natures]
  File "/usr/local/lib/python2.7/dist-packages/pymongo/cursor.py", line 1114, in next
    if len(self.__data) or self._refresh():
  File "/usr/local/lib/python2.7/dist-packages/pymongo/cursor.py", line 1036, in _refresh
    self.__collation))
  File "/usr/local/lib/python2.7/dist-packages/pymongo/cursor.py", line 873, in __send_message
    **kwargs)
  File "/usr/local/lib/python2.7/dist-packages/pymongo/mongo_client.py", line 888, in _send_message_with_response
    server = topology.select_server(selector)
  File "/usr/local/lib/python2.7/dist-packages/pymongo/topology.py", line 214, in select_server
    address))
  File "/usr/local/lib/python2.7/dist-packages/pymongo/topology.py", line 189, in select_servers
    self._error_message(selector))
pymongo.errors.ServerSelectionTimeoutError: localhost:27017: [Errno 111] Connection refused
Traceback (most recent call last):
  File "./proxy_verify/main_loop.py", line 37, in <module>
    app.run()
  File "./proxy_verify/main_loop.py", line 22, in run
    natures = self.schedule_manager.get_natures()
  File "/usr/local/code/ip_proxy/proxy_verify/schedule_manager.py", line 22, in get_natures
    natures = [ v for v in natures]
  File "/usr/local/lib/python2.7/dist-packages/pymongo/cursor.py", line 1114, in next
    if len(self.__data) or self._refresh():
  File "/usr/local/lib/python2.7/dist-packages/pymongo/cursor.py", line 1036, in _refresh
    self.__collation))
  File "/usr/local/lib/python2.7/dist-packages/pymongo/cursor.py", line 873, in __send_message
    **kwargs)
  File "/usr/local/lib/python2.7/dist-packages/pymongo/mongo_client.py", line 888, in _send_message_with_response
    server = topology.select_server(selector)
  File "/usr/local/lib/python2.7/dist-packages/pymongo/topology.py", line 214, in select_server
    address))
  File "/usr/local/lib/python2.7/dist-packages/pymongo/topology.py", line 189, in select_servers
    self._error_message(selector))
pymongo.errors.ServerSelectionTimeoutError: localhost:27017: [Errno 111] Connection refused
Traceback (most recent call last):
  File "./proxy_verify/main_loop.py", line 37, in <module>
    app.run()
  File "./proxy_verify/main_loop.py", line 22, in run
    natures = self.schedule_manager.get_natures()
  File "/usr/local/code/ip_proxy/proxy_verify/schedule_manager.py", line 22, in get_natures
    natures = [ v for v in natures]
  File "/usr/local/lib/python2.7/dist-packages/pymongo/cursor.py", line 1114, in next
    if len(self.__data) or self._refresh():
  File "/usr/local/lib/python2.7/dist-packages/pymongo/cursor.py", line 1036, in _refresh
    self.__collation))
  File "/usr/local/lib/python2.7/dist-packages/pymongo/cursor.py", line 873, in __send_message
    **kwargs)
  File "/usr/local/lib/python2.7/dist-packages/pymongo/mongo_client.py", line 888, in _send_message_with_response
    server = topology.select_server(selector)
  File "/usr/local/lib/python2.7/dist-packages/pymongo/topology.py", line 214, in select_server
    address))
  File "/usr/local/lib/python2.7/dist-packages/pymongo/topology.py", line 189, in select_servers
    self._error_message(selector))
pymongo.errors.ServerSelectionTimeoutError: localhost:27017: [Errno 111] Connection refused
Traceback (most recent call last):
  File "./proxy_verify/main_loop.py", line 37, in <module>
    app.run()
  File "./proxy_verify/main_loop.py", line 22, in run
    natures = self.schedule_manager.get_natures()
  File "/usr/local/code/ip_proxy/proxy_verify/schedule_manager.py", line 22, in get_natures
    natures = [ v for v in natures]
  File "/usr/local/lib/python2.7/dist-packages/pymongo/cursor.py", line 1114, in next
    if len(self.__data) or self._refresh():
  File "/usr/local/lib/python2.7/dist-packages/pymongo/cursor.py", line 1036, in _refresh
    self.__collation))
  File "/usr/local/lib/python2.7/dist-packages/pymongo/cursor.py", line 873, in __send_message
    **kwargs)
  File "/usr/local/lib/python2.7/dist-packages/pymongo/mongo_client.py", line 888, in _send_message_with_response
    server = topology.select_server(selector)
  File "/usr/local/lib/python2.7/dist-packages/pymongo/topology.py", line 214, in select_server
    address))
  File "/usr/local/lib/python2.7/dist-packages/pymongo/topology.py", line 189, in select_servers
    self._error_message(selector))
pymongo.errors.ServerSelectionTimeoutError: localhost:27017: [Errno 111] Connection refused
Traceback (most recent call last):
  File "./proxy_verify/main_loop.py", line 37, in <module>
    app.run()
  File "./proxy_verify/main_loop.py", line 22, in run
    natures = self.schedule_manager.get_natures()
  File "/usr/local/code/ip_proxy/proxy_verify/schedule_manager.py", line 22, in get_natures
    natures = [ v for v in natures]
  File "/usr/local/lib/python2.7/dist-packages/pymongo/cursor.py", line 1114, in next
    if len(self.__data) or self._refresh():
  File "/usr/local/lib/python2.7/dist-packages/pymongo/cursor.py", line 1036, in _refresh
    self.__collation))
  File "/usr/local/lib/python2.7/dist-packages/pymongo/cursor.py", line 873, in __send_message
    **kwargs)
  File "/usr/local/lib/python2.7/dist-packages/pymongo/mongo_client.py", line 888, in _send_message_with_response
    server = topology.select_server(selector)
  File "/usr/local/lib/python2.7/dist-packages/pymongo/topology.py", line 214, in select_server
    address))
  File "/usr/local/lib/python2.7/dist-packages/pymongo/topology.py", line 189, in select_servers
    self._error_message(selector))
pymongo.errors.ServerSelectionTimeoutError: localhost:27017: [Errno 111] Connection refused
Traceback (most recent call last):
  File "./proxy_verify/main_loop.py", line 37, in <module>
    app.run()
  File "./proxy_verify/main_loop.py", line 22, in run
    natures = self.schedule_manager.get_natures()
  File "/usr/local/code/ip_proxy/proxy_verify/schedule_manager.py", line 22, in get_natures
    natures = [ v for v in natures]
  File "/usr/local/lib/python2.7/dist-packages/pymongo/cursor.py", line 1114, in next
    if len(self.__data) or self._refresh():
  File "/usr/local/lib/python2.7/dist-packages/pymongo/cursor.py", line 1036, in _refresh
    self.__collation))
  File "/usr/local/lib/python2.7/dist-packages/pymongo/cursor.py", line 873, in __send_message
    **kwargs)
  File "/usr/local/lib/python2.7/dist-packages/pymongo/mongo_client.py", line 888, in _send_message_with_response
    server = topology.select_server(selector)
  File "/usr/local/lib/python2.7/dist-packages/pymongo/topology.py", line 214, in select_server
    address))
  File "/usr/local/lib/python2.7/dist-packages/pymongo/topology.py", line 189, in select_servers
    self._error_message(selector))
pymongo.errors.ServerSelectionTimeoutError: localhost:27017: [Errno 111] Connection refused
Traceback (most recent call last):
  File "./proxy_verify/main_loop.py", line 37, in <module>
    app.run()
  File "./proxy_verify/main_loop.py", line 22, in run
    natures = self.schedule_manager.get_natures()
  File "/usr/local/code/ip_proxy/proxy_verify/schedule_manager.py", line 22, in get_natures
    natures = [ v for v in natures]
  File "/usr/local/lib/python2.7/dist-packages/pymongo/cursor.py", line 1114, in next
    if len(self.__data) or self._refresh():
  File "/usr/local/lib/python2.7/dist-packages/pymongo/cursor.py", line 1036, in _refresh
    self.__collation))
  File "/usr/local/lib/python2.7/dist-packages/pymongo/cursor.py", line 873, in __send_message
    **kwargs)
  File "/usr/local/lib/python2.7/dist-packages/pymongo/mongo_client.py", line 888, in _send_message_with_response
    server = topology.select_server(selector)
  File "/usr/local/lib/python2.7/dist-packages/pymongo/topology.py", line 214, in select_server
    address))
  File "/usr/local/lib/python2.7/dist-packages/pymongo/topology.py", line 189, in select_servers
    self._error_message(selector))
pymongo.errors.ServerSelectionTimeoutError: localhost:27017: [Errno 111] Connection refused
Traceback (most recent call last):
  File "./proxy_verify/main_loop.py", line 37, in <module>
    app.run()
  File "./proxy_verify/main_loop.py", line 22, in run
    natures = self.schedule_manager.get_natures()
  File "/usr/local/code/ip_proxy/proxy_verify/schedule_manager.py", line 22, in get_natures
    natures = [ v for v in natures]
  File "/usr/local/lib/python2.7/dist-packages/pymongo/cursor.py", line 1114, in next
    if len(self.__data) or self._refresh():
  File "/usr/local/lib/python2.7/dist-packages/pymongo/cursor.py", line 1036, in _refresh
    self.__collation))
  File "/usr/local/lib/python2.7/dist-packages/pymongo/cursor.py", line 873, in __send_message
    **kwargs)
  File "/usr/local/lib/python2.7/dist-packages/pymongo/mongo_client.py", line 888, in _send_message_with_response
    server = topology.select_server(selector)
  File "/usr/local/lib/python2.7/dist-packages/pymongo/topology.py", line 214, in select_server
    address))
  File "/usr/local/lib/python2.7/dist-packages/pymongo/topology.py", line 189, in select_servers
    self._error_message(selector))
pymongo.errors.ServerSelectionTimeoutError: localhost:27017: [Errno 111] Connection refused
Traceback (most recent call last):
  File "./proxy_verify/main_loop.py", line 37, in <module>
    app.run()
  File "./proxy_verify/main_loop.py", line 22, in run
    natures = self.schedule_manager.get_natures()
  File "/usr/local/code/ip_proxy/proxy_verify/schedule_manager.py", line 22, in get_natures
    natures = [ v for v in natures]
  File "/usr/local/lib/python2.7/dist-packages/pymongo/cursor.py", line 1114, in next
    if len(self.__data) or self._refresh():
  File "/usr/local/lib/python2.7/dist-packages/pymongo/cursor.py", line 1036, in _refresh
    self.__collation))
  File "/usr/local/lib/python2.7/dist-packages/pymongo/cursor.py", line 873, in __send_message
    **kwargs)
  File "/usr/local/lib/python2.7/dist-packages/pymongo/mongo_client.py", line 888, in _send_message_with_response
    server = topology.select_server(selector)
  File "/usr/local/lib/python2.7/dist-packages/pymongo/topology.py", line 214, in select_server
    address))
  File "/usr/local/lib/python2.7/dist-packages/pymongo/topology.py", line 189, in select_servers
    self._error_message(selector))
pymongo.errors.ServerSelectionTimeoutError: localhost:27017: [Errno 111] Connection refused
Traceback (most recent call last):
  File "./proxy_verify/main_loop.py", line 37, in <module>
    app.run()
  File "./proxy_verify/main_loop.py", line 22, in run
    natures = self.schedule_manager.get_natures()
  File "/usr/local/code/ip_proxy/proxy_verify/schedule_manager.py", line 22, in get_natures
    natures = [ v for v in natures]
  File "/usr/local/lib/python2.7/dist-packages/pymongo/cursor.py", line 1114, in next
    if len(self.__data) or self._refresh():
  File "/usr/local/lib/python2.7/dist-packages/pymongo/cursor.py", line 1036, in _refresh
    self.__collation))
  File "/usr/local/lib/python2.7/dist-packages/pymongo/cursor.py", line 873, in __send_message
    **kwargs)
  File "/usr/local/lib/python2.7/dist-packages/pymongo/mongo_client.py", line 888, in _send_message_with_response
    server = topology.select_server(selector)
  File "/usr/local/lib/python2.7/dist-packages/pymongo/topology.py", line 214, in select_server
    address))
  File "/usr/local/lib/python2.7/dist-packages/pymongo/topology.py", line 189, in select_servers
    self._error_message(selector))
pymongo.errors.ServerSelectionTimeoutError: localhost:27017: [Errno 111] Connection refused
Traceback (most recent call last):
  File "./proxy_verify/main_loop.py", line 37, in <module>
    app.run()
  File "./proxy_verify/main_loop.py", line 22, in run
    natures = self.schedule_manager.get_natures()
  File "/usr/local/code/ip_proxy/proxy_verify/schedule_manager.py", line 22, in get_natures
    natures = [ v for v in natures]
  File "/usr/local/lib/python2.7/dist-packages/pymongo/cursor.py", line 1114, in next
    if len(self.__data) or self._refresh():
  File "/usr/local/lib/python2.7/dist-packages/pymongo/cursor.py", line 1036, in _refresh
    self.__collation))
  File "/usr/local/lib/python2.7/dist-packages/pymongo/cursor.py", line 873, in __send_message
    **kwargs)
  File "/usr/local/lib/python2.7/dist-packages/pymongo/mongo_client.py", line 888, in _send_message_with_response
    server = topology.select_server(selector)
  File "/usr/local/lib/python2.7/dist-packages/pymongo/topology.py", line 214, in select_server
    address))
  File "/usr/local/lib/python2.7/dist-packages/pymongo/topology.py", line 189, in select_servers
    self._error_message(selector))
pymongo.errors.ServerSelectionTimeoutError: localhost:27017: [Errno 111] Connection refused
Traceback (most recent call last):
  File "./proxy_verify/main_loop.py", line 37, in <module>
    app.run()
  File "./proxy_verify/main_loop.py", line 22, in run
    natures = self.schedule_manager.get_natures()
  File "/usr/local/code/ip_proxy/proxy_verify/schedule_manager.py", line 22, in get_natures
    natures = [ v for v in natures]
  File "/usr/local/lib/python2.7/dist-packages/pymongo/cursor.py", line 1114, in next
    if len(self.__data) or self._refresh():
  File "/usr/local/lib/python2.7/dist-packages/pymongo/cursor.py", line 1036, in _refresh
    self.__collation))
  File "/usr/local/lib/python2.7/dist-packages/pymongo/cursor.py", line 873, in __send_message
    **kwargs)
  File "/usr/local/lib/python2.7/dist-packages/pymongo/mongo_client.py", line 888, in _send_message_with_response
    server = topology.select_server(selector)
  File "/usr/local/lib/python2.7/dist-packages/pymongo/topology.py", line 214, in select_server
    address))
  File "/usr/local/lib/python2.7/dist-packages/pymongo/topology.py", line 189, in select_servers
    self._error_message(selector))
pymongo.errors.ServerSelectionTimeoutError: localhost:27017: [Errno 111] Connection refused
Traceback (most recent call last):
  File "./proxy_verify/main_loop.py", line 37, in <module>
    app.run()
  File "./proxy_verify/main_loop.py", line 22, in run
    natures = self.schedule_manager.get_natures()
  File "/usr/local/code/ip_proxy/proxy_verify/schedule_manager.py", line 22, in get_natures
    natures = [ v for v in natures]
  File "/usr/local/lib/python2.7/dist-packages/pymongo/cursor.py", line 1114, in next
    if len(self.__data) or self._refresh():
  File "/usr/local/lib/python2.7/dist-packages/pymongo/cursor.py", line 1036, in _refresh
    self.__collation))
  File "/usr/local/lib/python2.7/dist-packages/pymongo/cursor.py", line 873, in __send_message
    **kwargs)
  File "/usr/local/lib/python2.7/dist-packages/pymongo/mongo_client.py", line 888, in _send_message_with_response
    server = topology.select_server(selector)
  File "/usr/local/lib/python2.7/dist-packages/pymongo/topology.py", line 214, in select_server
    address))
  File "/usr/local/lib/python2.7/dist-packages/pymongo/topology.py", line 189, in select_servers
    self._error_message(selector))
pymongo.errors.ServerSelectionTimeoutError: localhost:27017: [Errno 111] Connection refused
Traceback (most recent call last):
  File "./proxy_verify/main_loop.py", line 37, in <module>
    app.run()
  File "./proxy_verify/main_loop.py", line 22, in run
    natures = self.schedule_manager.get_natures()
  File "/usr/local/code/ip_proxy/proxy_verify/schedule_manager.py", line 22, in get_natures
    natures = [ v for v in natures]
  File "/usr/local/lib/python2.7/dist-packages/pymongo/cursor.py", line 1114, in next
    if len(self.__data) or self._refresh():
  File "/usr/local/lib/python2.7/dist-packages/pymongo/cursor.py", line 1036, in _refresh
    self.__collation))
  File "/usr/local/lib/python2.7/dist-packages/pymongo/cursor.py", line 873, in __send_message
    **kwargs)
  File "/usr/local/lib/python2.7/dist-packages/pymongo/mongo_client.py", line 888, in _send_message_with_response
    server = topology.select_server(selector)
  File "/usr/local/lib/python2.7/dist-packages/pymongo/topology.py", line 214, in select_server
    address))
  File "/usr/local/lib/python2.7/dist-packages/pymongo/topology.py", line 189, in select_servers
    self._error_message(selector))
pymongo.errors.ServerSelectionTimeoutError: localhost:27017: [Errno 111] Connection refused
Traceback (most recent call last):
  File "./proxy_verify/main_loop.py", line 37, in <module>
    app.run()
  File "./proxy_verify/main_loop.py", line 22, in run
    natures = self.schedule_manager.get_natures()
  File "/usr/local/code/ip_proxy/proxy_verify/schedule_manager.py", line 22, in get_natures
    natures = [ v for v in natures]
  File "/usr/local/lib/python2.7/dist-packages/pymongo/cursor.py", line 1114, in next
    if len(self.__data) or self._refresh():
  File "/usr/local/lib/python2.7/dist-packages/pymongo/cursor.py", line 1036, in _refresh
    self.__collation))
  File "/usr/local/lib/python2.7/dist-packages/pymongo/cursor.py", line 873, in __send_message
    **kwargs)
  File "/usr/local/lib/python2.7/dist-packages/pymongo/mongo_client.py", line 888, in _send_message_with_response
    server = topology.select_server(selector)
  File "/usr/local/lib/python2.7/dist-packages/pymongo/topology.py", line 214, in select_server
    address))
  File "/usr/local/lib/python2.7/dist-packages/pymongo/topology.py", line 189, in select_servers
    self._error_message(selector))
pymongo.errors.ServerSelectionTimeoutError: localhost:27017: [Errno 111] Connection refused
Traceback (most recent call last):
  File "./proxy_verify/main_loop.py", line 37, in <module>
    app.run()
  File "./proxy_verify/main_loop.py", line 22, in run
    natures = self.schedule_manager.get_natures()
  File "/usr/local/code/ip_proxy/proxy_verify/schedule_manager.py", line 22, in get_natures
    natures = [ v for v in natures]
  File "/usr/local/lib/python2.7/dist-packages/pymongo/cursor.py", line 1114, in next
    if len(self.__data) or self._refresh():
  File "/usr/local/lib/python2.7/dist-packages/pymongo/cursor.py", line 1036, in _refresh
    self.__collation))
  File "/usr/local/lib/python2.7/dist-packages/pymongo/cursor.py", line 873, in __send_message
    **kwargs)
  File "/usr/local/lib/python2.7/dist-packages/pymongo/mongo_client.py", line 888, in _send_message_with_response
    server = topology.select_server(selector)
  File "/usr/local/lib/python2.7/dist-packages/pymongo/topology.py", line 214, in select_server
    address))
  File "/usr/local/lib/python2.7/dist-packages/pymongo/topology.py", line 189, in select_servers
    self._error_message(selector))
pymongo.errors.ServerSelectionTimeoutError: localhost:27017: [Errno 111] Connection refused
Traceback (most recent call last):
  File "./proxy_verify/main_loop.py", line 37, in <module>
    app.run()
  File "./proxy_verify/main_loop.py", line 22, in run
    natures = self.schedule_manager.get_natures()
  File "/usr/local/code/ip_proxy/proxy_verify/schedule_manager.py", line 22, in get_natures
    natures = [ v for v in natures]
  File "/usr/local/lib/python2.7/dist-packages/pymongo/cursor.py", line 1114, in next
    if len(self.__data) or self._refresh():
  File "/usr/local/lib/python2.7/dist-packages/pymongo/cursor.py", line 1036, in _refresh
    self.__collation))
  File "/usr/local/lib/python2.7/dist-packages/pymongo/cursor.py", line 873, in __send_message
    **kwargs)
  File "/usr/local/lib/python2.7/dist-packages/pymongo/mongo_client.py", line 888, in _send_message_with_response
    server = topology.select_server(selector)
  File "/usr/local/lib/python2.7/dist-packages/pymongo/topology.py", line 214, in select_server
    address))
  File "/usr/local/lib/python2.7/dist-packages/pymongo/topology.py", line 189, in select_servers
    self._error_message(selector))
pymongo.errors.ServerSelectionTimeoutError: localhost:27017: [Errno 111] Connection refused
Traceback (most recent call last):
  File "./proxy_verify/main_loop.py", line 37, in <module>
    app.run()
  File "./proxy_verify/main_loop.py", line 22, in run
    natures = self.schedule_manager.get_natures()
  File "/usr/local/code/ip_proxy/proxy_verify/schedule_manager.py", line 22, in get_natures
    natures = [ v for v in natures]
  File "/usr/local/lib/python2.7/dist-packages/pymongo/cursor.py", line 1114, in next
    if len(self.__data) or self._refresh():
  File "/usr/local/lib/python2.7/dist-packages/pymongo/cursor.py", line 1036, in _refresh
    self.__collation))
  File "/usr/local/lib/python2.7/dist-packages/pymongo/cursor.py", line 873, in __send_message
    **kwargs)
  File "/usr/local/lib/python2.7/dist-packages/pymongo/mongo_client.py", line 888, in _send_message_with_response
    server = topology.select_server(selector)
  File "/usr/local/lib/python2.7/dist-packages/pymongo/topology.py", line 214, in select_server
    address))
  File "/usr/local/lib/python2.7/dist-packages/pymongo/topology.py", line 189, in select_servers
    self._error_message(selector))
pymongo.errors.ServerSelectionTimeoutError: localhost:27017: [Errno 111] Connection refused
Traceback (most recent call last):
  File "./proxy_verify/main_loop.py", line 37, in <module>
    app.run()
  File "./proxy_verify/main_loop.py", line 22, in run
    natures = self.schedule_manager.get_natures()
  File "/usr/local/code/ip_proxy/proxy_verify/schedule_manager.py", line 22, in get_natures
    natures = [ v for v in natures]
  File "/usr/local/lib/python2.7/dist-packages/pymongo/cursor.py", line 1114, in next
    if len(self.__data) or self._refresh():
  File "/usr/local/lib/python2.7/dist-packages/pymongo/cursor.py", line 1036, in _refresh
    self.__collation))
  File "/usr/local/lib/python2.7/dist-packages/pymongo/cursor.py", line 873, in __send_message
    **kwargs)
  File "/usr/local/lib/python2.7/dist-packages/pymongo/mongo_client.py", line 888, in _send_message_with_response
    server = topology.select_server(selector)
  File "/usr/local/lib/python2.7/dist-packages/pymongo/topology.py", line 214, in select_server
    address))
  File "/usr/local/lib/python2.7/dist-packages/pymongo/topology.py", line 189, in select_servers
    self._error_message(selector))
pymongo.errors.ServerSelectionTimeoutError: localhost:27017: [Errno 111] Connection refused
Traceback (most recent call last):
  File "./proxy_verify/main_loop.py", line 37, in <module>
    app.run()
  File "./proxy_verify/main_loop.py", line 22, in run
    natures = self.schedule_manager.get_natures()
  File "/usr/local/code/ip_proxy/proxy_verify/schedule_manager.py", line 22, in get_natures
    natures = [ v for v in natures]
  File "/usr/local/lib/python2.7/dist-packages/pymongo/cursor.py", line 1114, in next
    if len(self.__data) or self._refresh():
  File "/usr/local/lib/python2.7/dist-packages/pymongo/cursor.py", line 1036, in _refresh
    self.__collation))
  File "/usr/local/lib/python2.7/dist-packages/pymongo/cursor.py", line 873, in __send_message
    **kwargs)
  File "/usr/local/lib/python2.7/dist-packages/pymongo/mongo_client.py", line 888, in _send_message_with_response
    server = topology.select_server(selector)
  File "/usr/local/lib/python2.7/dist-packages/pymongo/topology.py", line 214, in select_server
    address))
  File "/usr/local/lib/python2.7/dist-packages/pymongo/topology.py", line 189, in select_servers
    self._error_message(selector))
pymongo.errors.ServerSelectionTimeoutError: localhost:27017: [Errno 111] Connection refused
Traceback (most recent call last):
  File "./proxy_verify/main_loop.py", line 37, in <module>
    app.run()
  File "./proxy_verify/main_loop.py", line 22, in run
    natures = self.schedule_manager.get_natures()
  File "/usr/local/code/ip_proxy/proxy_verify/schedule_manager.py", line 22, in get_natures
    natures = [ v for v in natures]
  File "/usr/local/lib/python2.7/dist-packages/pymongo/cursor.py", line 1114, in next
    if len(self.__data) or self._refresh():
  File "/usr/local/lib/python2.7/dist-packages/pymongo/cursor.py", line 1036, in _refresh
    self.__collation))
  File "/usr/local/lib/python2.7/dist-packages/pymongo/cursor.py", line 873, in __send_message
    **kwargs)
  File "/usr/local/lib/python2.7/dist-packages/pymongo/mongo_client.py", line 888, in _send_message_with_response
    server = topology.select_server(selector)
  File "/usr/local/lib/python2.7/dist-packages/pymongo/topology.py", line 214, in select_server
    address))
  File "/usr/local/lib/python2.7/dist-packages/pymongo/topology.py", line 189, in select_servers
    self._error_message(selector))
pymongo.errors.ServerSelectionTimeoutError: localhost:27017: [Errno 111] Connection refused
Traceback (most recent call last):
  File "./proxy_verify/main_loop.py", line 37, in <module>
    app.run()
  File "./proxy_verify/main_loop.py", line 22, in run
    natures = self.schedule_manager.get_natures()
  File "/usr/local/code/ip_proxy/proxy_verify/schedule_manager.py", line 22, in get_natures
    natures = [ v for v in natures]
  File "/usr/local/lib/python2.7/dist-packages/pymongo/cursor.py", line 1114, in next
    if len(self.__data) or self._refresh():
  File "/usr/local/lib/python2.7/dist-packages/pymongo/cursor.py", line 1036, in _refresh
    self.__collation))
  File "/usr/local/lib/python2.7/dist-packages/pymongo/cursor.py", line 873, in __send_message
    **kwargs)
  File "/usr/local/lib/python2.7/dist-packages/pymongo/mongo_client.py", line 888, in _send_message_with_response
    server = topology.select_server(selector)
  File "/usr/local/lib/python2.7/dist-packages/pymongo/topology.py", line 214, in select_server
    address))
  File "/usr/local/lib/python2.7/dist-packages/pymongo/topology.py", line 189, in select_servers
    self._error_message(selector))
pymongo.errors.ServerSelectionTimeoutError: localhost:27017: [Errno 111] Connection refused
Traceback (most recent call last):
  File "./proxy_verify/main_loop.py", line 37, in <module>
    app.run()
  File "./proxy_verify/main_loop.py", line 22, in run
    natures = self.schedule_manager.get_natures()
  File "/usr/local/code/ip_proxy/proxy_verify/schedule_manager.py", line 22, in get_natures
    natures = [ v for v in natures]
  File "/usr/local/lib/python2.7/dist-packages/pymongo/cursor.py", line 1114, in next
    if len(self.__data) or self._refresh():
  File "/usr/local/lib/python2.7/dist-packages/pymongo/cursor.py", line 1036, in _refresh
    self.__collation))
  File "/usr/local/lib/python2.7/dist-packages/pymongo/cursor.py", line 873, in __send_message
    **kwargs)
  File "/usr/local/lib/python2.7/dist-packages/pymongo/mongo_client.py", line 888, in _send_message_with_response
    server = topology.select_server(selector)
  File "/usr/local/lib/python2.7/dist-packages/pymongo/topology.py", line 214, in select_server
    address))
  File "/usr/local/lib/python2.7/dist-packages/pymongo/topology.py", line 189, in select_servers
    self._error_message(selector))
pymongo.errors.ServerSelectionTimeoutError: localhost:27017: [Errno 111] Connection refused
Traceback (most recent call last):
  File "./proxy_verify/main_loop.py", line 37, in <module>
    app.run()
  File "./proxy_verify/main_loop.py", line 22, in run
    natures = self.schedule_manager.get_natures()
  File "/usr/local/code/ip_proxy/proxy_verify/schedule_manager.py", line 22, in get_natures
    natures = [ v for v in natures]
  File "/usr/local/lib/python2.7/dist-packages/pymongo/cursor.py", line 1114, in next
    if len(self.__data) or self._refresh():
  File "/usr/local/lib/python2.7/dist-packages/pymongo/cursor.py", line 1036, in _refresh
    self.__collation))
  File "/usr/local/lib/python2.7/dist-packages/pymongo/cursor.py", line 873, in __send_message
    **kwargs)
  File "/usr/local/lib/python2.7/dist-packages/pymongo/mongo_client.py", line 888, in _send_message_with_response
    server = topology.select_server(selector)
  File "/usr/local/lib/python2.7/dist-packages/pymongo/topology.py", line 214, in select_server
    address))
  File "/usr/local/lib/python2.7/dist-packages/pymongo/topology.py", line 189, in select_servers
    self._error_message(selector))
pymongo.errors.ServerSelectionTimeoutError: localhost:27017: [Errno 111] Connection refused
Traceback (most recent call last):
  File "./proxy_verify/main_loop.py", line 37, in <module>
    app.run()
  File "./proxy_verify/main_loop.py", line 22, in run
    natures = self.schedule_manager.get_natures()
  File "/usr/local/code/ip_proxy/proxy_verify/schedule_manager.py", line 22, in get_natures
    natures = [ v for v in natures]
  File "/usr/local/lib/python2.7/dist-packages/pymongo/cursor.py", line 1114, in next
    if len(self.__data) or self._refresh():
  File "/usr/local/lib/python2.7/dist-packages/pymongo/cursor.py", line 1036, in _refresh
    self.__collation))
  File "/usr/local/lib/python2.7/dist-packages/pymongo/cursor.py", line 873, in __send_message
    **kwargs)
  File "/usr/local/lib/python2.7/dist-packages/pymongo/mongo_client.py", line 888, in _send_message_with_response
    server = topology.select_server(selector)
  File "/usr/local/lib/python2.7/dist-packages/pymongo/topology.py", line 214, in select_server
    address))
  File "/usr/local/lib/python2.7/dist-packages/pymongo/topology.py", line 189, in select_servers
    self._error_message(selector))
pymongo.errors.ServerSelectionTimeoutError: localhost:27017: [Errno 111] Connection refused
Traceback (most recent call last):
  File "./proxy_verify/main_loop.py", line 37, in <module>
    app.run()
  File "./proxy_verify/main_loop.py", line 22, in run
    natures = self.schedule_manager.get_natures()
  File "/usr/local/code/ip_proxy/proxy_verify/schedule_manager.py", line 22, in get_natures
    natures = [ v for v in natures]
  File "/usr/local/lib/python2.7/dist-packages/pymongo/cursor.py", line 1114, in next
    if len(self.__data) or self._refresh():
  File "/usr/local/lib/python2.7/dist-packages/pymongo/cursor.py", line 1036, in _refresh
    self.__collation))
  File "/usr/local/lib/python2.7/dist-packages/pymongo/cursor.py", line 873, in __send_message
    **kwargs)
  File "/usr/local/lib/python2.7/dist-packages/pymongo/mongo_client.py", line 888, in _send_message_with_response
    server = topology.select_server(selector)
  File "/usr/local/lib/python2.7/dist-packages/pymongo/topology.py", line 214, in select_server
    address))
  File "/usr/local/lib/python2.7/dist-packages/pymongo/topology.py", line 189, in select_servers
    self._error_message(selector))
pymongo.errors.ServerSelectionTimeoutError: localhost:27017: [Errno 111] Connection refused
Traceback (most recent call last):
  File "./proxy_verify/main_loop.py", line 37, in <module>
    app.run()
  File "./proxy_verify/main_loop.py", line 22, in run
    natures = self.schedule_manager.get_natures()
  File "/usr/local/code/ip_proxy/proxy_verify/schedule_manager.py", line 22, in get_natures
    natures = [ v for v in natures]
  File "/usr/local/lib/python2.7/dist-packages/pymongo/cursor.py", line 1114, in next
    if len(self.__data) or self._refresh():
  File "/usr/local/lib/python2.7/dist-packages/pymongo/cursor.py", line 1036, in _refresh
    self.__collation))
  File "/usr/local/lib/python2.7/dist-packages/pymongo/cursor.py", line 873, in __send_message
    **kwargs)
  File "/usr/local/lib/python2.7/dist-packages/pymongo/mongo_client.py", line 888, in _send_message_with_response
    server = topology.select_server(selector)
  File "/usr/local/lib/python2.7/dist-packages/pymongo/topology.py", line 214, in select_server
    address))
  File "/usr/local/lib/python2.7/dist-packages/pymongo/topology.py", line 189, in select_servers
    self._error_message(selector))
pymongo.errors.ServerSelectionTimeoutError: localhost:27017: [Errno 111] Connection refused
Traceback (most recent call last):
  File "./proxy_verify/main_loop.py", line 37, in <module>
    app.run()
  File "./proxy_verify/main_loop.py", line 22, in run
    natures = self.schedule_manager.get_natures()
  File "/usr/local/code/ip_proxy/proxy_verify/schedule_manager.py", line 22, in get_natures
    natures = [ v for v in natures]
  File "/usr/local/lib/python2.7/dist-packages/pymongo/cursor.py", line 1114, in next
    if len(self.__data) or self._refresh():
  File "/usr/local/lib/python2.7/dist-packages/pymongo/cursor.py", line 1036, in _refresh
    self.__collation))
  File "/usr/local/lib/python2.7/dist-packages/pymongo/cursor.py", line 873, in __send_message
    **kwargs)
  File "/usr/local/lib/python2.7/dist-packages/pymongo/mongo_client.py", line 888, in _send_message_with_response
    server = topology.select_server(selector)
  File "/usr/local/lib/python2.7/dist-packages/pymongo/topology.py", line 214, in select_server
    address))
  File "/usr/local/lib/python2.7/dist-packages/pymongo/topology.py", line 189, in select_servers
    self._error_message(selector))
pymongo.errors.ServerSelectionTimeoutError: localhost:27017: [Errno 111] Connection refused
Traceback (most recent call last):
  File "./proxy_verify/main_loop.py", line 37, in <module>
    app.run()
  File "./proxy_verify/main_loop.py", line 22, in run
    natures = self.schedule_manager.get_natures()
  File "/usr/local/code/ip_proxy/proxy_verify/schedule_manager.py", line 22, in get_natures
    natures = [ v for v in natures]
  File "/usr/local/lib/python2.7/dist-packages/pymongo/cursor.py", line 1114, in next
    if len(self.__data) or self._refresh():
  File "/usr/local/lib/python2.7/dist-packages/pymongo/cursor.py", line 1036, in _refresh
    self.__collation))
  File "/usr/local/lib/python2.7/dist-packages/pymongo/cursor.py", line 873, in __send_message
    **kwargs)
  File "/usr/local/lib/python2.7/dist-packages/pymongo/mongo_client.py", line 888, in _send_message_with_response
    server = topology.select_server(selector)
  File "/usr/local/lib/python2.7/dist-packages/pymongo/topology.py", line 214, in select_server
    address))
  File "/usr/local/lib/python2.7/dist-packages/pymongo/topology.py", line 189, in select_servers
    self._error_message(selector))
pymongo.errors.ServerSelectionTimeoutError: localhost:27017: [Errno 111] Connection refused
Traceback (most recent call last):
  File "./proxy_verify/main_loop.py", line 37, in <module>
    app.run()
  File "./proxy_verify/main_loop.py", line 22, in run
    natures = self.schedule_manager.get_natures()
  File "/usr/local/code/ip_proxy/proxy_verify/schedule_manager.py", line 22, in get_natures
    natures = [ v for v in natures]
  File "/usr/local/lib/python2.7/dist-packages/pymongo/cursor.py", line 1114, in next
    if len(self.__data) or self._refresh():
  File "/usr/local/lib/python2.7/dist-packages/pymongo/cursor.py", line 1036, in _refresh
    self.__collation))
  File "/usr/local/lib/python2.7/dist-packages/pymongo/cursor.py", line 873, in __send_message
    **kwargs)
  File "/usr/local/lib/python2.7/dist-packages/pymongo/mongo_client.py", line 888, in _send_message_with_response
    server = topology.select_server(selector)
  File "/usr/local/lib/python2.7/dist-packages/pymongo/topology.py", line 214, in select_server
    address))
  File "/usr/local/lib/python2.7/dist-packages/pymongo/topology.py", line 189, in select_servers
    self._error_message(selector))
pymongo.errors.ServerSelectionTimeoutError: localhost:27017: [Errno 111] Connection refused
Traceback (most recent call last):
  File "./proxy_verify/main_loop.py", line 37, in <module>
    app.run()
  File "./proxy_verify/main_loop.py", line 22, in run
    natures = self.schedule_manager.get_natures()
  File "/usr/local/code/ip_proxy/proxy_verify/schedule_manager.py", line 22, in get_natures
    natures = [ v for v in natures]
  File "/usr/local/lib/python2.7/dist-packages/pymongo/cursor.py", line 1114, in next
    if len(self.__data) or self._refresh():
  File "/usr/local/lib/python2.7/dist-packages/pymongo/cursor.py", line 1036, in _refresh
    self.__collation))
  File "/usr/local/lib/python2.7/dist-packages/pymongo/cursor.py", line 873, in __send_message
    **kwargs)
  File "/usr/local/lib/python2.7/dist-packages/pymongo/mongo_client.py", line 888, in _send_message_with_response
    server = topology.select_server(selector)
  File "/usr/local/lib/python2.7/dist-packages/pymongo/topology.py", line 214, in select_server
    address))
  File "/usr/local/lib/python2.7/dist-packages/pymongo/topology.py", line 189, in select_servers
    self._error_message(selector))
pymongo.errors.ServerSelectionTimeoutError: localhost:27017: [Errno 111] Connection refused
Traceback (most recent call last):
  File "./proxy_verify/main_loop.py", line 37, in <module>
    app.run()
  File "./proxy_verify/main_loop.py", line 22, in run
    natures = self.schedule_manager.get_natures()
  File "/usr/local/code/ip_proxy/proxy_verify/schedule_manager.py", line 22, in get_natures
    natures = [ v for v in natures]
  File "/usr/local/lib/python2.7/dist-packages/pymongo/cursor.py", line 1114, in next
    if len(self.__data) or self._refresh():
  File "/usr/local/lib/python2.7/dist-packages/pymongo/cursor.py", line 1036, in _refresh
    self.__collation))
  File "/usr/local/lib/python2.7/dist-packages/pymongo/cursor.py", line 873, in __send_message
    **kwargs)
  File "/usr/local/lib/python2.7/dist-packages/pymongo/mongo_client.py", line 888, in _send_message_with_response
    server = topology.select_server(selector)
  File "/usr/local/lib/python2.7/dist-packages/pymongo/topology.py", line 214, in select_server
    address))
  File "/usr/local/lib/python2.7/dist-packages/pymongo/topology.py", line 189, in select_servers
    self._error_message(selector))
pymongo.errors.ServerSelectionTimeoutError: localhost:27017: [Errno 111] Connection refused
Traceback (most recent call last):
  File "./proxy_verify/main_loop.py", line 37, in <module>
    app.run()
  File "./proxy_verify/main_loop.py", line 22, in run
    natures = self.schedule_manager.get_natures()
  File "/usr/local/code/ip_proxy/proxy_verify/schedule_manager.py", line 22, in get_natures
    natures = [ v for v in natures]
  File "/usr/local/lib/python2.7/dist-packages/pymongo/cursor.py", line 1114, in next
    if len(self.__data) or self._refresh():
  File "/usr/local/lib/python2.7/dist-packages/pymongo/cursor.py", line 1036, in _refresh
    self.__collation))
  File "/usr/local/lib/python2.7/dist-packages/pymongo/cursor.py", line 873, in __send_message
    **kwargs)
  File "/usr/local/lib/python2.7/dist-packages/pymongo/mongo_client.py", line 888, in _send_message_with_response
    server = topology.select_server(selector)
  File "/usr/local/lib/python2.7/dist-packages/pymongo/topology.py", line 214, in select_server
    address))
  File "/usr/local/lib/python2.7/dist-packages/pymongo/topology.py", line 189, in select_servers
    self._error_message(selector))
pymongo.errors.ServerSelectionTimeoutError: localhost:27017: [Errno 111] Connection refused
/usr/local/lib/python2.7/dist-packages/pymongo/topology.py:145: UserWarning: MongoClient opened before fork. Create MongoClient with connect=False, or create client after forking. See PyMongo's documentation for details: http://api.mongodb.org/python/current/faq.html#pymongo-fork-safe>
  "MongoClient opened before fork. Create MongoClient "
2017-05-30 15:27:11 [scrapy.utils.log] INFO: Scrapy 1.4.0 started (bot: ip_proxy)
2017-05-30 15:27:11 [scrapy.utils.log] INFO: Overridden settings: {'NEWSPIDER_MODULE': 'ip_proxy.spiders', 'ROBOTSTXT_OBEY': True, 'SPIDER_MODULES': ['ip_proxy.spiders'], 'BOT_NAME': 'ip_proxy', 'USER_AGENT': 'Mozilla/5.0 (Macintosh; Intel Mac OS X 10_10_5) AppleWebKit/537.36 (KHTML, like Gecko) Chrome/58.0.3029.110 Safari/537.36', 'DOWNLOAD_DELAY': 3}
2017-05-30 15:27:11 [scrapy.middleware] INFO: Enabled extensions:
['scrapy.extensions.memusage.MemoryUsage',
 'scrapy.extensions.logstats.LogStats',
 'scrapy.extensions.telnet.TelnetConsole',
 'scrapy.extensions.corestats.CoreStats']
2017-05-30 15:27:11 [scrapy.middleware] INFO: Enabled downloader middlewares:
['scrapy.downloadermiddlewares.robotstxt.RobotsTxtMiddleware',
 'scrapy.downloadermiddlewares.httpauth.HttpAuthMiddleware',
 'scrapy.downloadermiddlewares.downloadtimeout.DownloadTimeoutMiddleware',
 'scrapy.downloadermiddlewares.defaultheaders.DefaultHeadersMiddleware',
 'scrapy.downloadermiddlewares.useragent.UserAgentMiddleware',
 'scrapy.downloadermiddlewares.retry.RetryMiddleware',
 'scrapy.downloadermiddlewares.redirect.MetaRefreshMiddleware',
 'scrapy.downloadermiddlewares.httpcompression.HttpCompressionMiddleware',
 'scrapy.downloadermiddlewares.redirect.RedirectMiddleware',
 'scrapy.downloadermiddlewares.cookies.CookiesMiddleware',
 'scrapy.downloadermiddlewares.httpproxy.HttpProxyMiddleware',
 'scrapy.downloadermiddlewares.stats.DownloaderStats']
2017-05-30 15:27:11 [scrapy.middleware] INFO: Enabled spider middlewares:
['scrapy.spidermiddlewares.httperror.HttpErrorMiddleware',
 'scrapy.spidermiddlewares.offsite.OffsiteMiddleware',
 'scrapy.spidermiddlewares.referer.RefererMiddleware',
 'scrapy.spidermiddlewares.urllength.UrlLengthMiddleware',
 'scrapy.spidermiddlewares.depth.DepthMiddleware']
2017-05-30 15:27:11 [root] DEBUG: Connect Mongo
2017-05-30 15:27:11 [root] DEBUG: Open Mongo localhost:27017
2017-05-30 15:27:11 [scrapy.middleware] INFO: Enabled item pipelines:
['ip_proxy.pipelines.IpProxyPipeline']
2017-05-30 15:27:11 [scrapy.core.engine] INFO: Spider opened
2017-05-30 15:27:11 [scrapy.extensions.logstats] INFO: Crawled 0 pages (at 0 pages/min), scraped 0 items (at 0 items/min)
2017-05-30 15:27:11 [scrapy.extensions.telnet] DEBUG: Telnet console listening on 127.0.0.1:6023
2017-05-30 15:27:12 [scrapy.core.engine] DEBUG: Crawled (200) <GET http://www.xicidaili.com/robots.txt> (referer: None)
2017-05-30 15:27:16 [scrapy.core.engine] DEBUG: Crawled (200) <GET http://www.xicidaili.com/nn/> (referer: None)
2017-05-30 15:27:16 [root] DEBUG: insert One
/usr/local/lib/python2.7/dist-packages/pymongo/topology.py:145: UserWarning: MongoClient opened before fork. Create MongoClient with connect=False, or create client after forking. See PyMongo's documentation for details: http://api.mongodb.org/python/current/faq.html#pymongo-fork-safe>
  "MongoClient opened before fork. Create MongoClient "
2017-05-30 15:28:10 [scrapy.utils.log] INFO: Scrapy 1.4.0 started (bot: ip_proxy)
2017-05-30 15:28:10 [scrapy.utils.log] INFO: Overridden settings: {'NEWSPIDER_MODULE': 'ip_proxy.spiders', 'ROBOTSTXT_OBEY': True, 'SPIDER_MODULES': ['ip_proxy.spiders'], 'BOT_NAME': 'ip_proxy', 'USER_AGENT': 'Mozilla/5.0 (Macintosh; Intel Mac OS X 10_10_5) AppleWebKit/537.36 (KHTML, like Gecko) Chrome/58.0.3029.110 Safari/537.36', 'DOWNLOAD_DELAY': 3}
2017-05-30 15:28:10 [scrapy.middleware] INFO: Enabled extensions:
['scrapy.extensions.memusage.MemoryUsage',
 'scrapy.extensions.logstats.LogStats',
 'scrapy.extensions.telnet.TelnetConsole',
 'scrapy.extensions.corestats.CoreStats']
2017-05-30 15:28:10 [scrapy.middleware] INFO: Enabled downloader middlewares:
['scrapy.downloadermiddlewares.robotstxt.RobotsTxtMiddleware',
 'scrapy.downloadermiddlewares.httpauth.HttpAuthMiddleware',
 'scrapy.downloadermiddlewares.downloadtimeout.DownloadTimeoutMiddleware',
 'scrapy.downloadermiddlewares.defaultheaders.DefaultHeadersMiddleware',
 'scrapy.downloadermiddlewares.useragent.UserAgentMiddleware',
 'scrapy.downloadermiddlewares.retry.RetryMiddleware',
 'scrapy.downloadermiddlewares.redirect.MetaRefreshMiddleware',
 'scrapy.downloadermiddlewares.httpcompression.HttpCompressionMiddleware',
 'scrapy.downloadermiddlewares.redirect.RedirectMiddleware',
 'scrapy.downloadermiddlewares.cookies.CookiesMiddleware',
 'scrapy.downloadermiddlewares.httpproxy.HttpProxyMiddleware',
 'scrapy.downloadermiddlewares.stats.DownloaderStats']
2017-05-30 15:28:10 [scrapy.middleware] INFO: Enabled spider middlewares:
['scrapy.spidermiddlewares.httperror.HttpErrorMiddleware',
 'scrapy.spidermiddlewares.offsite.OffsiteMiddleware',
 'scrapy.spidermiddlewares.referer.RefererMiddleware',
 'scrapy.spidermiddlewares.urllength.UrlLengthMiddleware',
 'scrapy.spidermiddlewares.depth.DepthMiddleware']
2017-05-30 15:28:10 [root] DEBUG: Connect Mongo
2017-05-30 15:28:10 [root] DEBUG: Open Mongo localhost:27017
2017-05-30 15:28:10 [scrapy.middleware] INFO: Enabled item pipelines:
['ip_proxy.pipelines.IpProxyPipeline']
2017-05-30 15:28:10 [scrapy.core.engine] INFO: Spider opened
2017-05-30 15:28:10 [scrapy.extensions.logstats] INFO: Crawled 0 pages (at 0 pages/min), scraped 0 items (at 0 items/min)
2017-05-30 15:28:10 [scrapy.extensions.telnet] DEBUG: Telnet console listening on 127.0.0.1:6023
2017-05-30 15:28:10 [scrapy.core.engine] DEBUG: Crawled (200) <GET http://www.xicidaili.com/robots.txt> (referer: None)
2017-05-30 15:28:13 [scrapy.core.engine] DEBUG: Crawled (200) <GET http://www.xicidaili.com/nn/> (referer: None)
2017-05-30 15:28:14 [root] DEBUG: insert One
